[2024-12-17T06:50:03.473+0000] {taskinstance.py:1157} INFO - Dependencies all met for dep_context=non-requeueable deps ti=<TaskInstance: full_name_dag.load_data scheduled__2024-12-16T00:00:00+00:00 [queued]>
[2024-12-17T06:50:03.485+0000] {taskinstance.py:1157} INFO - Dependencies all met for dep_context=requeueable deps ti=<TaskInstance: full_name_dag.load_data scheduled__2024-12-16T00:00:00+00:00 [queued]>
[2024-12-17T06:50:03.486+0000] {taskinstance.py:1359} INFO - Starting attempt 1 of 2
[2024-12-17T06:50:03.569+0000] {taskinstance.py:1380} INFO - Executing <Task(PythonOperator): load_data> on 2024-12-16 00:00:00+00:00
[2024-12-17T06:50:03.577+0000] {standard_task_runner.py:57} INFO - Started process 9925 to run task
[2024-12-17T06:50:03.581+0000] {standard_task_runner.py:84} INFO - Running: ['***', 'tasks', 'run', 'full_name_dag', 'load_data', 'scheduled__2024-12-16T00:00:00+00:00', '--job-id', '114', '--raw', '--subdir', 'DAGS_FOLDER/full_name_dag.py', '--cfg-path', '/tmp/tmpca4r054u']
[2024-12-17T06:50:03.584+0000] {standard_task_runner.py:85} INFO - Job 114: Subtask load_data
[2024-12-17T06:50:03.662+0000] {logging_mixin.py:151} WARNING - /home/***/.local/lib/python3.8/site-packages/***/settings.py:195 DeprecationWarning: The sql_alchemy_conn option in [core] has been moved to the sql_alchemy_conn option in [database] - the old setting has been used, but please update your config.
[2024-12-17T06:50:03.697+0000] {task_command.py:415} INFO - Running <TaskInstance: full_name_dag.load_data scheduled__2024-12-16T00:00:00+00:00 [running]> on host cfbf61ae1f16
[2024-12-17T06:50:03.829+0000] {taskinstance.py:1660} INFO - Exporting env vars: AIRFLOW_CTX_DAG_OWNER='***' AIRFLOW_CTX_DAG_ID='full_name_dag' AIRFLOW_CTX_TASK_ID='load_data' AIRFLOW_CTX_EXECUTION_DATE='2024-12-16T00:00:00+00:00' AIRFLOW_CTX_TRY_NUMBER='1' AIRFLOW_CTX_DAG_RUN_ID='scheduled__2024-12-16T00:00:00+00:00'
[2024-12-17T06:50:03.863+0000] {base.py:73} INFO - Using connection ID 'admin' for task execution.
[2024-12-17T06:50:06.251+0000] {python.py:194} INFO - Done. Returned value was: None
[2024-12-17T06:50:06.264+0000] {taskinstance.py:1398} INFO - Marking task as SUCCESS. dag_id=full_name_dag, task_id=load_data, execution_date=20241216T000000, start_date=20241217T065003, end_date=20241217T065006
[2024-12-17T06:50:06.322+0000] {local_task_job_runner.py:228} INFO - Task exited with return code 0
[2024-12-17T06:50:06.343+0000] {taskinstance.py:2776} INFO - 1 downstream tasks scheduled from follow-on schedule check
[2024-12-17T09:12:21.328+0000] {taskinstance.py:1157} INFO - Dependencies all met for dep_context=non-requeueable deps ti=<TaskInstance: full_name_dag.load_data scheduled__2024-12-16T00:00:00+00:00 [queued]>
[2024-12-17T09:12:21.430+0000] {taskinstance.py:1157} INFO - Dependencies all met for dep_context=requeueable deps ti=<TaskInstance: full_name_dag.load_data scheduled__2024-12-16T00:00:00+00:00 [queued]>
[2024-12-17T09:12:21.430+0000] {taskinstance.py:1359} INFO - Starting attempt 1 of 2
[2024-12-17T09:12:21.443+0000] {taskinstance.py:1380} INFO - Executing <Task(PythonOperator): load_data> on 2024-12-16 00:00:00+00:00
[2024-12-17T09:12:21.447+0000] {standard_task_runner.py:57} INFO - Started process 12658 to run task
[2024-12-17T09:12:21.450+0000] {standard_task_runner.py:84} INFO - Running: ['***', 'tasks', 'run', 'full_name_dag', 'load_data', 'scheduled__2024-12-16T00:00:00+00:00', '--job-id', '128', '--raw', '--subdir', 'DAGS_FOLDER/full_name_dag.py', '--cfg-path', '/tmp/tmpn98ndl9r']
[2024-12-17T09:12:21.453+0000] {standard_task_runner.py:85} INFO - Job 128: Subtask load_data
[2024-12-17T09:12:21.471+0000] {logging_mixin.py:151} WARNING - /home/***/.local/lib/python3.8/site-packages/***/settings.py:195 DeprecationWarning: The sql_alchemy_conn option in [core] has been moved to the sql_alchemy_conn option in [database] - the old setting has been used, but please update your config.
[2024-12-17T09:12:21.510+0000] {task_command.py:415} INFO - Running <TaskInstance: full_name_dag.load_data scheduled__2024-12-16T00:00:00+00:00 [running]> on host cfbf61ae1f16
[2024-12-17T09:12:21.590+0000] {taskinstance.py:1660} INFO - Exporting env vars: AIRFLOW_CTX_DAG_OWNER='***' AIRFLOW_CTX_DAG_ID='full_name_dag' AIRFLOW_CTX_TASK_ID='load_data' AIRFLOW_CTX_EXECUTION_DATE='2024-12-16T00:00:00+00:00' AIRFLOW_CTX_TRY_NUMBER='1' AIRFLOW_CTX_DAG_RUN_ID='scheduled__2024-12-16T00:00:00+00:00'
[2024-12-17T09:12:21.608+0000] {base.py:73} INFO - Using connection ID 'admin' for task execution.
[2024-12-17T09:12:21.636+0000] {taskinstance.py:1935} ERROR - Task failed with exception
Traceback (most recent call last):
  File "/home/airflow/.local/lib/python3.8/site-packages/sqlalchemy/engine/base.py", line 1910, in _execute_context
    self.dialect.do_execute(
  File "/home/airflow/.local/lib/python3.8/site-packages/sqlalchemy/engine/default.py", line 736, in do_execute
    cursor.execute(statement, parameters)
psycopg2.errors.UndefinedColumn: column full_name.tab_id does not exist
LINE 1: SELECT full_name.tab_id AS full_name_tab_id, full_name.name ...
               ^
HINT:  Perhaps you meant to reference the column "full_name.tab_num".


The above exception was the direct cause of the following exception:

Traceback (most recent call last):
  File "/home/airflow/.local/lib/python3.8/site-packages/airflow/operators/python.py", line 192, in execute
    return_value = self.execute_callable()
  File "/home/airflow/.local/lib/python3.8/site-packages/airflow/operators/python.py", line 209, in execute_callable
    return self.python_callable(*self.op_args, **self.op_kwargs)
  File "/opt/airflow/dags/full_name_dag.py", line 51, in load_data_to_db
    record = session.query(Fullname).filter_by(tab_id=row['tab_id']).first()
  File "/home/airflow/.local/lib/python3.8/site-packages/sqlalchemy/orm/query.py", line 2824, in first
    return self.limit(1)._iter().first()
  File "/home/airflow/.local/lib/python3.8/site-packages/sqlalchemy/orm/query.py", line 2916, in _iter
    result = self.session.execute(
  File "/home/airflow/.local/lib/python3.8/site-packages/sqlalchemy/orm/session.py", line 1717, in execute
    result = conn._execute_20(statement, params or {}, execution_options)
  File "/home/airflow/.local/lib/python3.8/site-packages/sqlalchemy/engine/base.py", line 1710, in _execute_20
    return meth(self, args_10style, kwargs_10style, execution_options)
  File "/home/airflow/.local/lib/python3.8/site-packages/sqlalchemy/sql/elements.py", line 334, in _execute_on_connection
    return connection._execute_clauseelement(
  File "/home/airflow/.local/lib/python3.8/site-packages/sqlalchemy/engine/base.py", line 1577, in _execute_clauseelement
    ret = self._execute_context(
  File "/home/airflow/.local/lib/python3.8/site-packages/sqlalchemy/engine/base.py", line 1953, in _execute_context
    self._handle_dbapi_exception(
  File "/home/airflow/.local/lib/python3.8/site-packages/sqlalchemy/engine/base.py", line 2134, in _handle_dbapi_exception
    util.raise_(
  File "/home/airflow/.local/lib/python3.8/site-packages/sqlalchemy/util/compat.py", line 211, in raise_
    raise exception
  File "/home/airflow/.local/lib/python3.8/site-packages/sqlalchemy/engine/base.py", line 1910, in _execute_context
    self.dialect.do_execute(
  File "/home/airflow/.local/lib/python3.8/site-packages/sqlalchemy/engine/default.py", line 736, in do_execute
    cursor.execute(statement, parameters)
sqlalchemy.exc.ProgrammingError: (psycopg2.errors.UndefinedColumn) column full_name.tab_id does not exist
LINE 1: SELECT full_name.tab_id AS full_name_tab_id, full_name.name ...
               ^
HINT:  Perhaps you meant to reference the column "full_name.tab_num".

[SQL: SELECT full_name.tab_id AS full_name_tab_id, full_name.name AS full_name_name, full_name.surname AS full_name_surname, full_name.patronymic AS full_name_patronymic 
FROM full_name 
WHERE full_name.tab_id = %(tab_id_1)s 
 LIMIT %(param_1)s]
[parameters: {'tab_id_1': 100, 'param_1': 1}]
(Background on this error at: https://sqlalche.me/e/14/f405)
[2024-12-17T09:12:21.651+0000] {taskinstance.py:1398} INFO - Marking task as UP_FOR_RETRY. dag_id=full_name_dag, task_id=load_data, execution_date=20241216T000000, start_date=20241217T091221, end_date=20241217T091221
[2024-12-17T09:12:21.660+0000] {standard_task_runner.py:104} ERROR - Failed to execute job 128 for task load_data ((psycopg2.errors.UndefinedColumn) column full_name.tab_id does not exist
LINE 1: SELECT full_name.tab_id AS full_name_tab_id, full_name.name ...
               ^
HINT:  Perhaps you meant to reference the column "full_name.tab_num".

[SQL: SELECT full_name.tab_id AS full_name_tab_id, full_name.name AS full_name_name, full_name.surname AS full_name_surname, full_name.patronymic AS full_name_patronymic 
FROM full_name 
WHERE full_name.tab_id = %(tab_id_1)s 
 LIMIT %(param_1)s]
[parameters: {'tab_id_1': 100, 'param_1': 1}]
(Background on this error at: https://sqlalche.me/e/14/f405); 12658)
[2024-12-17T09:12:21.704+0000] {local_task_job_runner.py:228} INFO - Task exited with return code 1
[2024-12-17T09:12:21.720+0000] {taskinstance.py:2776} INFO - 0 downstream tasks scheduled from follow-on schedule check
[2024-12-17T09:13:10.022+0000] {taskinstance.py:1157} INFO - Dependencies all met for dep_context=non-requeueable deps ti=<TaskInstance: full_name_dag.load_data scheduled__2024-12-16T00:00:00+00:00 [queued]>
[2024-12-17T09:13:10.030+0000] {taskinstance.py:1157} INFO - Dependencies all met for dep_context=requeueable deps ti=<TaskInstance: full_name_dag.load_data scheduled__2024-12-16T00:00:00+00:00 [queued]>
[2024-12-17T09:13:10.030+0000] {taskinstance.py:1359} INFO - Starting attempt 1 of 2
[2024-12-17T09:13:10.042+0000] {taskinstance.py:1380} INFO - Executing <Task(PythonOperator): load_data> on 2024-12-16 00:00:00+00:00
[2024-12-17T09:13:10.046+0000] {standard_task_runner.py:57} INFO - Started process 12699 to run task
[2024-12-17T09:13:10.050+0000] {standard_task_runner.py:84} INFO - Running: ['***', 'tasks', 'run', 'full_name_dag', 'load_data', 'scheduled__2024-12-16T00:00:00+00:00', '--job-id', '134', '--raw', '--subdir', 'DAGS_FOLDER/full_name_dag.py', '--cfg-path', '/tmp/tmpagusb82d']
[2024-12-17T09:13:10.052+0000] {standard_task_runner.py:85} INFO - Job 134: Subtask load_data
[2024-12-17T09:13:10.068+0000] {logging_mixin.py:151} WARNING - /home/***/.local/lib/python3.8/site-packages/***/settings.py:195 DeprecationWarning: The sql_alchemy_conn option in [core] has been moved to the sql_alchemy_conn option in [database] - the old setting has been used, but please update your config.
[2024-12-17T09:13:10.105+0000] {task_command.py:415} INFO - Running <TaskInstance: full_name_dag.load_data scheduled__2024-12-16T00:00:00+00:00 [running]> on host cfbf61ae1f16
[2024-12-17T09:13:10.186+0000] {taskinstance.py:1660} INFO - Exporting env vars: AIRFLOW_CTX_DAG_OWNER='***' AIRFLOW_CTX_DAG_ID='full_name_dag' AIRFLOW_CTX_TASK_ID='load_data' AIRFLOW_CTX_EXECUTION_DATE='2024-12-16T00:00:00+00:00' AIRFLOW_CTX_TRY_NUMBER='1' AIRFLOW_CTX_DAG_RUN_ID='scheduled__2024-12-16T00:00:00+00:00'
[2024-12-17T09:13:10.204+0000] {base.py:73} INFO - Using connection ID 'admin' for task execution.
[2024-12-17T09:13:10.233+0000] {taskinstance.py:1935} ERROR - Task failed with exception
Traceback (most recent call last):
  File "/home/airflow/.local/lib/python3.8/site-packages/sqlalchemy/engine/base.py", line 1910, in _execute_context
    self.dialect.do_execute(
  File "/home/airflow/.local/lib/python3.8/site-packages/sqlalchemy/engine/default.py", line 736, in do_execute
    cursor.execute(statement, parameters)
psycopg2.errors.UndefinedColumn: column full_name.tab_id does not exist
LINE 1: SELECT full_name.tab_id AS full_name_tab_id, full_name.name ...
               ^
HINT:  Perhaps you meant to reference the column "full_name.tab_num".


The above exception was the direct cause of the following exception:

Traceback (most recent call last):
  File "/home/airflow/.local/lib/python3.8/site-packages/airflow/operators/python.py", line 192, in execute
    return_value = self.execute_callable()
  File "/home/airflow/.local/lib/python3.8/site-packages/airflow/operators/python.py", line 209, in execute_callable
    return self.python_callable(*self.op_args, **self.op_kwargs)
  File "/opt/airflow/dags/full_name_dag.py", line 51, in load_data_to_db
    record = session.query(Fullname).filter_by(tab_id=row['tab_id']).first()
  File "/home/airflow/.local/lib/python3.8/site-packages/sqlalchemy/orm/query.py", line 2824, in first
    return self.limit(1)._iter().first()
  File "/home/airflow/.local/lib/python3.8/site-packages/sqlalchemy/orm/query.py", line 2916, in _iter
    result = self.session.execute(
  File "/home/airflow/.local/lib/python3.8/site-packages/sqlalchemy/orm/session.py", line 1717, in execute
    result = conn._execute_20(statement, params or {}, execution_options)
  File "/home/airflow/.local/lib/python3.8/site-packages/sqlalchemy/engine/base.py", line 1710, in _execute_20
    return meth(self, args_10style, kwargs_10style, execution_options)
  File "/home/airflow/.local/lib/python3.8/site-packages/sqlalchemy/sql/elements.py", line 334, in _execute_on_connection
    return connection._execute_clauseelement(
  File "/home/airflow/.local/lib/python3.8/site-packages/sqlalchemy/engine/base.py", line 1577, in _execute_clauseelement
    ret = self._execute_context(
  File "/home/airflow/.local/lib/python3.8/site-packages/sqlalchemy/engine/base.py", line 1953, in _execute_context
    self._handle_dbapi_exception(
  File "/home/airflow/.local/lib/python3.8/site-packages/sqlalchemy/engine/base.py", line 2134, in _handle_dbapi_exception
    util.raise_(
  File "/home/airflow/.local/lib/python3.8/site-packages/sqlalchemy/util/compat.py", line 211, in raise_
    raise exception
  File "/home/airflow/.local/lib/python3.8/site-packages/sqlalchemy/engine/base.py", line 1910, in _execute_context
    self.dialect.do_execute(
  File "/home/airflow/.local/lib/python3.8/site-packages/sqlalchemy/engine/default.py", line 736, in do_execute
    cursor.execute(statement, parameters)
sqlalchemy.exc.ProgrammingError: (psycopg2.errors.UndefinedColumn) column full_name.tab_id does not exist
LINE 1: SELECT full_name.tab_id AS full_name_tab_id, full_name.name ...
               ^
HINT:  Perhaps you meant to reference the column "full_name.tab_num".

[SQL: SELECT full_name.tab_id AS full_name_tab_id, full_name.name AS full_name_name, full_name.surname AS full_name_surname, full_name.patronymic AS full_name_patronymic 
FROM full_name 
WHERE full_name.tab_id = %(tab_id_1)s 
 LIMIT %(param_1)s]
[parameters: {'tab_id_1': 100, 'param_1': 1}]
(Background on this error at: https://sqlalche.me/e/14/f405)
[2024-12-17T09:13:10.248+0000] {taskinstance.py:1398} INFO - Marking task as UP_FOR_RETRY. dag_id=full_name_dag, task_id=load_data, execution_date=20241216T000000, start_date=20241217T091310, end_date=20241217T091310
[2024-12-17T09:13:10.258+0000] {standard_task_runner.py:104} ERROR - Failed to execute job 134 for task load_data ((psycopg2.errors.UndefinedColumn) column full_name.tab_id does not exist
LINE 1: SELECT full_name.tab_id AS full_name_tab_id, full_name.name ...
               ^
HINT:  Perhaps you meant to reference the column "full_name.tab_num".

[SQL: SELECT full_name.tab_id AS full_name_tab_id, full_name.name AS full_name_name, full_name.surname AS full_name_surname, full_name.patronymic AS full_name_patronymic 
FROM full_name 
WHERE full_name.tab_id = %(tab_id_1)s 
 LIMIT %(param_1)s]
[parameters: {'tab_id_1': 100, 'param_1': 1}]
(Background on this error at: https://sqlalche.me/e/14/f405); 12699)
[2024-12-17T09:13:10.303+0000] {local_task_job_runner.py:228} INFO - Task exited with return code 1
[2024-12-17T09:13:10.320+0000] {taskinstance.py:2776} INFO - 0 downstream tasks scheduled from follow-on schedule check
