[2024-12-24T18:46:00.016+0000] {taskinstance.py:1157} INFO - Dependencies all met for dep_context=non-requeueable deps ti=<TaskInstance: shift_table_sick_leave_dag.load_data manual__2024-12-24T18:40:57.256892+00:00 [queued]>
[2024-12-24T18:46:00.023+0000] {taskinstance.py:1157} INFO - Dependencies all met for dep_context=requeueable deps ti=<TaskInstance: shift_table_sick_leave_dag.load_data manual__2024-12-24T18:40:57.256892+00:00 [queued]>
[2024-12-24T18:46:00.024+0000] {taskinstance.py:1359} INFO - Starting attempt 2 of 2
[2024-12-24T18:46:00.037+0000] {taskinstance.py:1380} INFO - Executing <Task(PythonOperator): load_data> on 2024-12-24 18:40:57.256892+00:00
[2024-12-24T18:46:00.041+0000] {standard_task_runner.py:57} INFO - Started process 1091 to run task
[2024-12-24T18:46:00.043+0000] {standard_task_runner.py:84} INFO - Running: ['***', 'tasks', 'run', 'shift_table_sick_leave_dag', 'load_data', 'manual__2024-12-24T18:40:57.256892+00:00', '--job-id', '194', '--raw', '--subdir', 'DAGS_FOLDER/shift_table_sick_leave_dag.py', '--cfg-path', '/tmp/tmpck8xid5t']
[2024-12-24T18:46:00.046+0000] {standard_task_runner.py:85} INFO - Job 194: Subtask load_data
[2024-12-24T18:46:00.064+0000] {logging_mixin.py:151} WARNING - /home/***/.local/lib/python3.8/site-packages/***/settings.py:195 DeprecationWarning: The sql_alchemy_conn option in [core] has been moved to the sql_alchemy_conn option in [database] - the old setting has been used, but please update your config.
[2024-12-24T18:46:00.102+0000] {task_command.py:415} INFO - Running <TaskInstance: shift_table_sick_leave_dag.load_data manual__2024-12-24T18:40:57.256892+00:00 [running]> on host e335f8873093
[2024-12-24T18:46:00.183+0000] {taskinstance.py:1660} INFO - Exporting env vars: AIRFLOW_CTX_DAG_OWNER='***' AIRFLOW_CTX_DAG_ID='shift_table_sick_leave_dag' AIRFLOW_CTX_TASK_ID='load_data' AIRFLOW_CTX_EXECUTION_DATE='2024-12-24T18:40:57.256892+00:00' AIRFLOW_CTX_TRY_NUMBER='2' AIRFLOW_CTX_DAG_RUN_ID='manual__2024-12-24T18:40:57.256892+00:00'
[2024-12-24T18:46:00.323+0000] {base.py:73} INFO - Using connection ID 'admin' for task execution.
[2024-12-24T18:46:00.361+0000] {taskinstance.py:1935} ERROR - Task failed with exception
Traceback (most recent call last):
  File "/home/airflow/.local/lib/python3.8/site-packages/sqlalchemy/engine/base.py", line 1910, in _execute_context
    self.dialect.do_execute(
  File "/home/airflow/.local/lib/python3.8/site-packages/sqlalchemy/engine/default.py", line 736, in do_execute
    cursor.execute(statement, parameters)
psycopg2.errors.ForeignKeyViolation: insert or update on table "shift_table" violates foreign key constraint "shift_table_object_fkey"
DETAIL:  Key (object)=(2) is not present in table "object".


The above exception was the direct cause of the following exception:

Traceback (most recent call last):
  File "/home/airflow/.local/lib/python3.8/site-packages/airflow/operators/python.py", line 192, in execute
    return_value = self.execute_callable()
  File "/home/airflow/.local/lib/python3.8/site-packages/airflow/operators/python.py", line 209, in execute_callable
    return self.python_callable(*self.op_args, **self.op_kwargs)
  File "/opt/airflow/dags/shift_table_sick_leave_dag.py", line 34, in load_data_to_db
    record = session.query(ShiftTable).filter_by(num=row['num']).first()
  File "/home/airflow/.local/lib/python3.8/site-packages/sqlalchemy/orm/query.py", line 2824, in first
    return self.limit(1)._iter().first()
  File "/home/airflow/.local/lib/python3.8/site-packages/sqlalchemy/orm/query.py", line 2916, in _iter
    result = self.session.execute(
  File "/home/airflow/.local/lib/python3.8/site-packages/sqlalchemy/orm/session.py", line 1665, in execute
    ) = compile_state_cls.orm_pre_session_exec(
  File "/home/airflow/.local/lib/python3.8/site-packages/sqlalchemy/orm/context.py", line 312, in orm_pre_session_exec
    session._autoflush()
  File "/home/airflow/.local/lib/python3.8/site-packages/sqlalchemy/orm/session.py", line 2264, in _autoflush
    util.raise_(e, with_traceback=sys.exc_info()[2])
  File "/home/airflow/.local/lib/python3.8/site-packages/sqlalchemy/util/compat.py", line 211, in raise_
    raise exception
  File "/home/airflow/.local/lib/python3.8/site-packages/sqlalchemy/orm/session.py", line 2253, in _autoflush
    self.flush()
  File "/home/airflow/.local/lib/python3.8/site-packages/sqlalchemy/orm/session.py", line 3449, in flush
    self._flush(objects)
  File "/home/airflow/.local/lib/python3.8/site-packages/sqlalchemy/orm/session.py", line 3589, in _flush
    transaction.rollback(_capture_exception=True)
  File "/home/airflow/.local/lib/python3.8/site-packages/sqlalchemy/util/langhelpers.py", line 70, in __exit__
    compat.raise_(
  File "/home/airflow/.local/lib/python3.8/site-packages/sqlalchemy/util/compat.py", line 211, in raise_
    raise exception
  File "/home/airflow/.local/lib/python3.8/site-packages/sqlalchemy/orm/session.py", line 3549, in _flush
    flush_context.execute()
  File "/home/airflow/.local/lib/python3.8/site-packages/sqlalchemy/orm/unitofwork.py", line 456, in execute
    rec.execute(self)
  File "/home/airflow/.local/lib/python3.8/site-packages/sqlalchemy/orm/unitofwork.py", line 630, in execute
    util.preloaded.orm_persistence.save_obj(
  File "/home/airflow/.local/lib/python3.8/site-packages/sqlalchemy/orm/persistence.py", line 245, in save_obj
    _emit_insert_statements(
  File "/home/airflow/.local/lib/python3.8/site-packages/sqlalchemy/orm/persistence.py", line 1097, in _emit_insert_statements
    c = connection._execute_20(
  File "/home/airflow/.local/lib/python3.8/site-packages/sqlalchemy/engine/base.py", line 1710, in _execute_20
    return meth(self, args_10style, kwargs_10style, execution_options)
  File "/home/airflow/.local/lib/python3.8/site-packages/sqlalchemy/sql/elements.py", line 334, in _execute_on_connection
    return connection._execute_clauseelement(
  File "/home/airflow/.local/lib/python3.8/site-packages/sqlalchemy/engine/base.py", line 1577, in _execute_clauseelement
    ret = self._execute_context(
  File "/home/airflow/.local/lib/python3.8/site-packages/sqlalchemy/engine/base.py", line 1953, in _execute_context
    self._handle_dbapi_exception(
  File "/home/airflow/.local/lib/python3.8/site-packages/sqlalchemy/engine/base.py", line 2134, in _handle_dbapi_exception
    util.raise_(
  File "/home/airflow/.local/lib/python3.8/site-packages/sqlalchemy/util/compat.py", line 211, in raise_
    raise exception
  File "/home/airflow/.local/lib/python3.8/site-packages/sqlalchemy/engine/base.py", line 1910, in _execute_context
    self.dialect.do_execute(
  File "/home/airflow/.local/lib/python3.8/site-packages/sqlalchemy/engine/default.py", line 736, in do_execute
    cursor.execute(statement, parameters)
sqlalchemy.exc.IntegrityError: (raised as a result of Query-invoked autoflush; consider using a session.no_autoflush block if this flush is occurring prematurely)
(psycopg2.errors.ForeignKeyViolation) insert or update on table "shift_table" violates foreign key constraint "shift_table_object_fkey"
DETAIL:  Key (object)=(2) is not present in table "object".

[SQL: INSERT INTO shift_table (num, tab_id, sector, object, change, address, date) VALUES (%(num)s, %(tab_id)s, %(sector)s, %(object)s, %(change)s, %(address)s, %(date)s)]
[parameters: {'num': 2, 'tab_id': 101, 'sector': 500, 'object': 2, 'change': 1, 'address': 'г.Москва', 'date': datetime.date(2024, 12, 14)}]
(Background on this error at: https://sqlalche.me/e/14/gkpj)
[2024-12-24T18:46:00.376+0000] {taskinstance.py:1398} INFO - Marking task as FAILED. dag_id=shift_table_sick_leave_dag, task_id=load_data, execution_date=20241224T184057, start_date=20241224T184600, end_date=20241224T184600
[2024-12-24T18:46:00.387+0000] {standard_task_runner.py:104} ERROR - Failed to execute job 194 for task load_data ((raised as a result of Query-invoked autoflush; consider using a session.no_autoflush block if this flush is occurring prematurely)
(psycopg2.errors.ForeignKeyViolation) insert or update on table "shift_table" violates foreign key constraint "shift_table_object_fkey"
DETAIL:  Key (object)=(2) is not present in table "object".

[SQL: INSERT INTO shift_table (num, tab_id, sector, object, change, address, date) VALUES (%(num)s, %(tab_id)s, %(sector)s, %(object)s, %(change)s, %(address)s, %(date)s)]
[parameters: {'num': 2, 'tab_id': 101, 'sector': 500, 'object': 2, 'change': 1, 'address': 'г.Москва', 'date': datetime.date(2024, 12, 14)}]
(Background on this error at: https://sqlalche.me/e/14/gkpj); 1091)
[2024-12-24T18:46:00.417+0000] {local_task_job_runner.py:228} INFO - Task exited with return code 1
[2024-12-24T18:46:00.438+0000] {taskinstance.py:2776} INFO - 0 downstream tasks scheduled from follow-on schedule check
