[2024-12-24T10:51:47.058+0000] {taskinstance.py:1157} INFO - Dependencies all met for dep_context=non-requeueable deps ti=<TaskInstance: shift_table_sick_leave_dag.load_data scheduled__2024-12-22T15:00:00+00:00 [queued]>
[2024-12-24T10:51:47.133+0000] {taskinstance.py:1157} INFO - Dependencies all met for dep_context=requeueable deps ti=<TaskInstance: shift_table_sick_leave_dag.load_data scheduled__2024-12-22T15:00:00+00:00 [queued]>
[2024-12-24T10:51:47.134+0000] {taskinstance.py:1359} INFO - Starting attempt 1 of 2
[2024-12-24T10:51:47.145+0000] {taskinstance.py:1380} INFO - Executing <Task(PythonOperator): load_data> on 2024-12-22 15:00:00+00:00
[2024-12-24T10:51:47.149+0000] {standard_task_runner.py:57} INFO - Started process 6092 to run task
[2024-12-24T10:51:47.152+0000] {standard_task_runner.py:84} INFO - Running: ['***', 'tasks', 'run', 'shift_table_sick_leave_dag', 'load_data', 'scheduled__2024-12-22T15:00:00+00:00', '--job-id', '185', '--raw', '--subdir', 'DAGS_FOLDER/shift_table_sick_leave_dag.py', '--cfg-path', '/tmp/tmp53qe10zu']
[2024-12-24T10:51:47.154+0000] {standard_task_runner.py:85} INFO - Job 185: Subtask load_data
[2024-12-24T10:51:47.172+0000] {logging_mixin.py:151} WARNING - /home/***/.local/lib/python3.8/site-packages/***/settings.py:195 DeprecationWarning: The sql_alchemy_conn option in [core] has been moved to the sql_alchemy_conn option in [database] - the old setting has been used, but please update your config.
[2024-12-24T10:51:47.208+0000] {task_command.py:415} INFO - Running <TaskInstance: shift_table_sick_leave_dag.load_data scheduled__2024-12-22T15:00:00+00:00 [running]> on host 3c36be7478f9
[2024-12-24T10:51:47.283+0000] {taskinstance.py:1660} INFO - Exporting env vars: AIRFLOW_CTX_DAG_OWNER='***' AIRFLOW_CTX_DAG_ID='shift_table_sick_leave_dag' AIRFLOW_CTX_TASK_ID='load_data' AIRFLOW_CTX_EXECUTION_DATE='2024-12-22T15:00:00+00:00' AIRFLOW_CTX_TRY_NUMBER='1' AIRFLOW_CTX_DAG_RUN_ID='scheduled__2024-12-22T15:00:00+00:00'
[2024-12-24T10:51:47.487+0000] {base.py:73} INFO - Using connection ID 'admin' for task execution.
[2024-12-24T10:51:47.527+0000] {taskinstance.py:1935} ERROR - Task failed with exception
Traceback (most recent call last):
  File "/home/airflow/.local/lib/python3.8/site-packages/airflow/operators/python.py", line 192, in execute
    return_value = self.execute_callable()
  File "/home/airflow/.local/lib/python3.8/site-packages/airflow/operators/python.py", line 209, in execute_callable
    return self.python_callable(*self.op_args, **self.op_kwargs)
  File "/opt/airflow/dags/shift_table_sick_leave_dag.py", line 55, in load_data_to_db
    record = session.query(ShiftTable).filter_by(num=row['num']).first()
  File "/home/airflow/.local/lib/python3.8/site-packages/sqlalchemy/orm/query.py", line 2824, in first
    return self.limit(1)._iter().first()
  File "/home/airflow/.local/lib/python3.8/site-packages/sqlalchemy/orm/query.py", line 2916, in _iter
    result = self.session.execute(
  File "/home/airflow/.local/lib/python3.8/site-packages/sqlalchemy/orm/session.py", line 1665, in execute
    ) = compile_state_cls.orm_pre_session_exec(
  File "/home/airflow/.local/lib/python3.8/site-packages/sqlalchemy/orm/context.py", line 312, in orm_pre_session_exec
    session._autoflush()
  File "/home/airflow/.local/lib/python3.8/site-packages/sqlalchemy/orm/session.py", line 2253, in _autoflush
    self.flush()
  File "/home/airflow/.local/lib/python3.8/site-packages/sqlalchemy/orm/session.py", line 3449, in flush
    self._flush(objects)
  File "/home/airflow/.local/lib/python3.8/site-packages/sqlalchemy/orm/session.py", line 3589, in _flush
    transaction.rollback(_capture_exception=True)
  File "/home/airflow/.local/lib/python3.8/site-packages/sqlalchemy/util/langhelpers.py", line 70, in __exit__
    compat.raise_(
  File "/home/airflow/.local/lib/python3.8/site-packages/sqlalchemy/util/compat.py", line 211, in raise_
    raise exception
  File "/home/airflow/.local/lib/python3.8/site-packages/sqlalchemy/orm/session.py", line 3549, in _flush
    flush_context.execute()
  File "/home/airflow/.local/lib/python3.8/site-packages/sqlalchemy/orm/unitofwork.py", line 456, in execute
    rec.execute(self)
  File "/home/airflow/.local/lib/python3.8/site-packages/sqlalchemy/orm/unitofwork.py", line 630, in execute
    util.preloaded.orm_persistence.save_obj(
  File "/home/airflow/.local/lib/python3.8/site-packages/sqlalchemy/orm/persistence.py", line 228, in save_obj
    for table, mapper in base_mapper._sorted_tables.items():
  File "/home/airflow/.local/lib/python3.8/site-packages/sqlalchemy/util/langhelpers.py", line 1184, in __get__
    obj.__dict__[self.__name__] = result = self.fget(obj)
  File "/home/airflow/.local/lib/python3.8/site-packages/sqlalchemy/orm/mapper.py", line 3386, in _sorted_tables
    sorted_ = sql_util.sort_tables(
  File "/home/airflow/.local/lib/python3.8/site-packages/sqlalchemy/sql/ddl.py", line 1217, in sort_tables
    for (t, fkcs) in sort_tables_and_constraints(
  File "/home/airflow/.local/lib/python3.8/site-packages/sqlalchemy/sql/ddl.py", line 1289, in sort_tables_and_constraints
    filtered = filter_fn(fkc)
  File "/home/airflow/.local/lib/python3.8/site-packages/sqlalchemy/sql/ddl.py", line 1207, in _skip_fn
    if skip_fn(fk):
  File "/home/airflow/.local/lib/python3.8/site-packages/sqlalchemy/orm/mapper.py", line 3369, in skip
    dep = table_to_mapper.get(fk.column.table)
  File "/home/airflow/.local/lib/python3.8/site-packages/sqlalchemy/util/langhelpers.py", line 1113, in __get__
    obj.__dict__[self.__name__] = result = self.fget(obj)
  File "/home/airflow/.local/lib/python3.8/site-packages/sqlalchemy/sql/schema.py", line 2532, in column
    return self._resolve_column()
  File "/home/airflow/.local/lib/python3.8/site-packages/sqlalchemy/sql/schema.py", line 2543, in _resolve_column
    raise exc.NoReferencedTableError(
sqlalchemy.exc.NoReferencedTableError: Foreign key associated with column 'shift_table.tab_id' could not find table 'full_name' with which to generate a foreign key to target column 'tab_id'
[2024-12-24T10:51:47.554+0000] {taskinstance.py:1398} INFO - Marking task as UP_FOR_RETRY. dag_id=shift_table_sick_leave_dag, task_id=load_data, execution_date=20241222T150000, start_date=20241224T105147, end_date=20241224T105147
[2024-12-24T10:51:47.566+0000] {standard_task_runner.py:104} ERROR - Failed to execute job 185 for task load_data (Foreign key associated with column 'shift_table.tab_id' could not find table 'full_name' with which to generate a foreign key to target column 'tab_id'; 6092)
[2024-12-24T10:51:47.605+0000] {local_task_job_runner.py:228} INFO - Task exited with return code 1
[2024-12-24T10:51:47.624+0000] {taskinstance.py:2776} INFO - 0 downstream tasks scheduled from follow-on schedule check
