[2024-12-24T21:09:35.980+0000] {taskinstance.py:1157} INFO - Dependencies all met for dep_context=non-requeueable deps ti=<TaskInstance: education_inventory_medical_object_vocation_dag.load_data_5 manual__2024-12-24T21:04:22.389232+00:00 [queued]>
[2024-12-24T21:09:35.988+0000] {taskinstance.py:1157} INFO - Dependencies all met for dep_context=requeueable deps ti=<TaskInstance: education_inventory_medical_object_vocation_dag.load_data_5 manual__2024-12-24T21:04:22.389232+00:00 [queued]>
[2024-12-24T21:09:35.989+0000] {taskinstance.py:1359} INFO - Starting attempt 1 of 2
[2024-12-24T21:09:36.001+0000] {taskinstance.py:1380} INFO - Executing <Task(PythonOperator): load_data_5> on 2024-12-24 21:04:22.389232+00:00
[2024-12-24T21:09:36.005+0000] {standard_task_runner.py:57} INFO - Started process 3226 to run task
[2024-12-24T21:09:36.008+0000] {standard_task_runner.py:84} INFO - Running: ['***', 'tasks', 'run', 'education_inventory_medical_object_vocation_dag', 'load_data_5', 'manual__2024-12-24T21:04:22.389232+00:00', '--job-id', '234', '--raw', '--subdir', 'DAGS_FOLDER/education_inventory_medical_object_vocation_dag.py', '--cfg-path', '/tmp/tmp98e33kfs']
[2024-12-24T21:09:36.010+0000] {standard_task_runner.py:85} INFO - Job 234: Subtask load_data_5
[2024-12-24T21:09:36.028+0000] {logging_mixin.py:151} WARNING - /home/***/.local/lib/python3.8/site-packages/***/settings.py:195 DeprecationWarning: The sql_alchemy_conn option in [core] has been moved to the sql_alchemy_conn option in [database] - the old setting has been used, but please update your config.
[2024-12-24T21:09:36.067+0000] {task_command.py:415} INFO - Running <TaskInstance: education_inventory_medical_object_vocation_dag.load_data_5 manual__2024-12-24T21:04:22.389232+00:00 [running]> on host f7bedf4d7c26
[2024-12-24T21:09:36.150+0000] {taskinstance.py:1660} INFO - Exporting env vars: AIRFLOW_CTX_DAG_OWNER='***' AIRFLOW_CTX_DAG_ID='education_inventory_medical_object_vocation_dag' AIRFLOW_CTX_TASK_ID='load_data_5' AIRFLOW_CTX_EXECUTION_DATE='2024-12-24T21:04:22.389232+00:00' AIRFLOW_CTX_TRY_NUMBER='1' AIRFLOW_CTX_DAG_RUN_ID='manual__2024-12-24T21:04:22.389232+00:00'
[2024-12-24T21:09:36.479+0000] {base.py:73} INFO - Using connection ID 'admin' for task execution.
[2024-12-24T21:09:36.485+0000] {taskinstance.py:1935} ERROR - Task failed with exception
Traceback (most recent call last):
  File "/home/airflow/.local/lib/python3.8/site-packages/pandas/core/indexes/base.py", line 3653, in get_loc
    return self._engine.get_loc(casted_key)
  File "pandas/_libs/index.pyx", line 147, in pandas._libs.index.IndexEngine.get_loc
  File "pandas/_libs/index.pyx", line 176, in pandas._libs.index.IndexEngine.get_loc
  File "pandas/_libs/hashtable_class_helper.pxi", line 7080, in pandas._libs.hashtable.PyObjectHashTable.get_item
  File "pandas/_libs/hashtable_class_helper.pxi", line 7088, in pandas._libs.hashtable.PyObjectHashTable.get_item
KeyError: 'vacation_end_1'

The above exception was the direct cause of the following exception:

Traceback (most recent call last):
  File "/home/airflow/.local/lib/python3.8/site-packages/airflow/operators/python.py", line 192, in execute
    return_value = self.execute_callable()
  File "/home/airflow/.local/lib/python3.8/site-packages/airflow/operators/python.py", line 209, in execute_callable
    return self.python_callable(*self.op_args, **self.op_kwargs)
  File "/opt/airflow/dags/education_inventory_medical_object_vocation_dag.py", line 99, in load_data_to_db_5
    row['vacation_end_1'] = pd.to_datetime(row['vacation_end_1']).date()
  File "/home/airflow/.local/lib/python3.8/site-packages/pandas/core/series.py", line 1007, in __getitem__
    return self._get_value(key)
  File "/home/airflow/.local/lib/python3.8/site-packages/pandas/core/series.py", line 1116, in _get_value
    loc = self.index.get_loc(label)
  File "/home/airflow/.local/lib/python3.8/site-packages/pandas/core/indexes/base.py", line 3655, in get_loc
    raise KeyError(key) from err
KeyError: 'vacation_end_1'
[2024-12-24T21:09:36.499+0000] {taskinstance.py:1398} INFO - Marking task as UP_FOR_RETRY. dag_id=education_inventory_medical_object_vocation_dag, task_id=load_data_5, execution_date=20241224T210422, start_date=20241224T210935, end_date=20241224T210936
[2024-12-24T21:09:36.511+0000] {standard_task_runner.py:104} ERROR - Failed to execute job 234 for task load_data_5 ('vacation_end_1'; 3226)
[2024-12-24T21:09:36.542+0000] {local_task_job_runner.py:228} INFO - Task exited with return code 1
[2024-12-24T21:09:36.559+0000] {taskinstance.py:2776} INFO - 0 downstream tasks scheduled from follow-on schedule check
