[2024-12-16T18:49:35.537+0000] {taskinstance.py:1157} INFO - Dependencies all met for dep_context=non-requeueable deps ti=<TaskInstance: sick_leave_etl_dag.load_data manual__2024-12-16T18:44:30.567046+00:00 [queued]>
[2024-12-16T18:49:35.544+0000] {taskinstance.py:1157} INFO - Dependencies all met for dep_context=requeueable deps ti=<TaskInstance: sick_leave_etl_dag.load_data manual__2024-12-16T18:44:30.567046+00:00 [queued]>
[2024-12-16T18:49:35.545+0000] {taskinstance.py:1359} INFO - Starting attempt 2 of 2
[2024-12-16T18:49:35.557+0000] {taskinstance.py:1380} INFO - Executing <Task(PythonOperator): load_data> on 2024-12-16 18:44:30.567046+00:00
[2024-12-16T18:49:35.561+0000] {standard_task_runner.py:57} INFO - Started process 4737 to run task
[2024-12-16T18:49:35.563+0000] {standard_task_runner.py:84} INFO - Running: ['***', 'tasks', 'run', 'sick_leave_etl_dag', 'load_data', 'manual__2024-12-16T18:44:30.567046+00:00', '--job-id', '35', '--raw', '--subdir', 'DAGS_FOLDER/sick_leave_dag.py', '--cfg-path', '/tmp/tmpo5o4wy6j']
[2024-12-16T18:49:35.566+0000] {standard_task_runner.py:85} INFO - Job 35: Subtask load_data
[2024-12-16T18:49:35.583+0000] {logging_mixin.py:151} WARNING - /home/***/.local/lib/python3.8/site-packages/***/settings.py:195 DeprecationWarning: The sql_alchemy_conn option in [core] has been moved to the sql_alchemy_conn option in [database] - the old setting has been used, but please update your config.
[2024-12-16T18:49:35.616+0000] {task_command.py:415} INFO - Running <TaskInstance: sick_leave_etl_dag.load_data manual__2024-12-16T18:44:30.567046+00:00 [running]> on host cfbf61ae1f16
[2024-12-16T18:49:35.701+0000] {taskinstance.py:1660} INFO - Exporting env vars: AIRFLOW_CTX_DAG_OWNER='***' AIRFLOW_CTX_DAG_ID='sick_leave_etl_dag' AIRFLOW_CTX_TASK_ID='load_data' AIRFLOW_CTX_EXECUTION_DATE='2024-12-16T18:44:30.567046+00:00' AIRFLOW_CTX_TRY_NUMBER='2' AIRFLOW_CTX_DAG_RUN_ID='manual__2024-12-16T18:44:30.567046+00:00'
[2024-12-16T18:49:35.717+0000] {base.py:73} INFO - Using connection ID 'admin' for task execution.
[2024-12-16T18:49:35.743+0000] {taskinstance.py:1935} ERROR - Task failed with exception
Traceback (most recent call last):
  File "/home/airflow/.local/lib/python3.8/site-packages/pandas/core/indexes/base.py", line 3653, in get_loc
    return self._engine.get_loc(casted_key)
  File "pandas/_libs/index.pyx", line 147, in pandas._libs.index.IndexEngine.get_loc
  File "pandas/_libs/index.pyx", line 176, in pandas._libs.index.IndexEngine.get_loc
  File "pandas/_libs/hashtable_class_helper.pxi", line 7080, in pandas._libs.hashtable.PyObjectHashTable.get_item
  File "pandas/_libs/hashtable_class_helper.pxi", line 7088, in pandas._libs.hashtable.PyObjectHashTable.get_item
KeyError: 'num'

The above exception was the direct cause of the following exception:

Traceback (most recent call last):
  File "/home/airflow/.local/lib/python3.8/site-packages/airflow/operators/python.py", line 192, in execute
    return_value = self.execute_callable()
  File "/home/airflow/.local/lib/python3.8/site-packages/airflow/operators/python.py", line 209, in execute_callable
    return self.python_callable(*self.op_args, **self.op_kwargs)
  File "/opt/airflow/dags/sick_leave_dag.py", line 66, in load_data_to_db
    record = session.query(SickLeave).filter_by(num=row['num']).first()
  File "/home/airflow/.local/lib/python3.8/site-packages/pandas/core/series.py", line 1007, in __getitem__
    return self._get_value(key)
  File "/home/airflow/.local/lib/python3.8/site-packages/pandas/core/series.py", line 1116, in _get_value
    loc = self.index.get_loc(label)
  File "/home/airflow/.local/lib/python3.8/site-packages/pandas/core/indexes/base.py", line 3655, in get_loc
    raise KeyError(key) from err
KeyError: 'num'
[2024-12-16T18:49:35.756+0000] {taskinstance.py:1398} INFO - Marking task as FAILED. dag_id=sick_leave_etl_dag, task_id=load_data, execution_date=20241216T184430, start_date=20241216T184935, end_date=20241216T184935
[2024-12-16T18:49:35.766+0000] {standard_task_runner.py:104} ERROR - Failed to execute job 35 for task load_data ('num'; 4737)
[2024-12-16T18:49:35.776+0000] {local_task_job_runner.py:228} INFO - Task exited with return code 1
[2024-12-16T18:49:35.792+0000] {taskinstance.py:2776} INFO - 0 downstream tasks scheduled from follow-on schedule check
