[2024-12-20T20:26:04.079+0000] {taskinstance.py:1157} INFO - Dependencies all met for dep_context=non-requeueable deps ti=<TaskInstance: full_name_and_data_users_dag.load_data_2 scheduled__2024-12-16T00:00:00+00:00 [queued]>
[2024-12-20T20:26:04.157+0000] {taskinstance.py:1157} INFO - Dependencies all met for dep_context=requeueable deps ti=<TaskInstance: full_name_and_data_users_dag.load_data_2 scheduled__2024-12-16T00:00:00+00:00 [queued]>
[2024-12-20T20:26:04.158+0000] {taskinstance.py:1359} INFO - Starting attempt 1 of 2
[2024-12-20T20:26:04.170+0000] {taskinstance.py:1380} INFO - Executing <Task(PythonOperator): load_data_2> on 2024-12-16 00:00:00+00:00
[2024-12-20T20:26:04.174+0000] {standard_task_runner.py:57} INFO - Started process 3894 to run task
[2024-12-20T20:26:04.176+0000] {standard_task_runner.py:84} INFO - Running: ['***', 'tasks', 'run', 'full_name_and_data_users_dag', 'load_data_2', 'scheduled__2024-12-16T00:00:00+00:00', '--job-id', '164', '--raw', '--subdir', 'DAGS_FOLDER/full_name_data_users_dag.py', '--cfg-path', '/tmp/tmpe9wntu2t']
[2024-12-20T20:26:04.178+0000] {standard_task_runner.py:85} INFO - Job 164: Subtask load_data_2
[2024-12-20T20:26:04.194+0000] {logging_mixin.py:151} WARNING - /home/***/.local/lib/python3.8/site-packages/***/settings.py:195 DeprecationWarning: The sql_alchemy_conn option in [core] has been moved to the sql_alchemy_conn option in [database] - the old setting has been used, but please update your config.
[2024-12-20T20:26:04.243+0000] {task_command.py:415} INFO - Running <TaskInstance: full_name_and_data_users_dag.load_data_2 scheduled__2024-12-16T00:00:00+00:00 [running]> on host 150cfac62d06
[2024-12-20T20:26:04.319+0000] {taskinstance.py:1660} INFO - Exporting env vars: AIRFLOW_CTX_DAG_OWNER='***' AIRFLOW_CTX_DAG_ID='full_name_and_data_users_dag' AIRFLOW_CTX_TASK_ID='load_data_2' AIRFLOW_CTX_EXECUTION_DATE='2024-12-16T00:00:00+00:00' AIRFLOW_CTX_TRY_NUMBER='1' AIRFLOW_CTX_DAG_RUN_ID='scheduled__2024-12-16T00:00:00+00:00'
[2024-12-20T20:26:04.621+0000] {base.py:73} INFO - Using connection ID 'admin' for task execution.
[2024-12-20T20:26:04.646+0000] {taskinstance.py:1935} ERROR - Task failed with exception
Traceback (most recent call last):
  File "/home/airflow/.local/lib/python3.8/site-packages/pandas/core/indexes/base.py", line 3653, in get_loc
    return self._engine.get_loc(casted_key)
  File "pandas/_libs/index.pyx", line 147, in pandas._libs.index.IndexEngine.get_loc
  File "pandas/_libs/index.pyx", line 176, in pandas._libs.index.IndexEngine.get_loc
  File "pandas/_libs/hashtable_class_helper.pxi", line 7080, in pandas._libs.hashtable.PyObjectHashTable.get_item
  File "pandas/_libs/hashtable_class_helper.pxi", line 7088, in pandas._libs.hashtable.PyObjectHashTable.get_item
KeyError: 'date_birth'

The above exception was the direct cause of the following exception:

Traceback (most recent call last):
  File "/home/airflow/.local/lib/python3.8/site-packages/airflow/operators/python.py", line 192, in execute
    return_value = self.execute_callable()
  File "/home/airflow/.local/lib/python3.8/site-packages/airflow/operators/python.py", line 209, in execute_callable
    return self.python_callable(*self.op_args, **self.op_kwargs)
  File "/opt/airflow/dags/full_name_data_users_dag.py", line 83, in load_data_to_db_2
    row['date_birth'] = pd.to_datetime(row['date_birth']).date() if not pd.isnull(row['date_birth']) else None
  File "/home/airflow/.local/lib/python3.8/site-packages/pandas/core/series.py", line 1007, in __getitem__
    return self._get_value(key)
  File "/home/airflow/.local/lib/python3.8/site-packages/pandas/core/series.py", line 1116, in _get_value
    loc = self.index.get_loc(label)
  File "/home/airflow/.local/lib/python3.8/site-packages/pandas/core/indexes/base.py", line 3655, in get_loc
    raise KeyError(key) from err
KeyError: 'date_birth'
[2024-12-20T20:26:04.659+0000] {taskinstance.py:1398} INFO - Marking task as UP_FOR_RETRY. dag_id=full_name_and_data_users_dag, task_id=load_data_2, execution_date=20241216T000000, start_date=20241220T202604, end_date=20241220T202604
[2024-12-20T20:26:04.672+0000] {standard_task_runner.py:104} ERROR - Failed to execute job 164 for task load_data_2 ('date_birth'; 3894)
[2024-12-20T20:26:04.710+0000] {local_task_job_runner.py:228} INFO - Task exited with return code 1
[2024-12-20T20:26:04.726+0000] {taskinstance.py:2776} INFO - 0 downstream tasks scheduled from follow-on schedule check
