[2024-12-17T09:28:19.100+0000] {taskinstance.py:1157} INFO - Dependencies all met for dep_context=non-requeueable deps ti=<TaskInstance: sick_leave_etl_dag.load_data manual__2024-12-17T09:28:14.856420+00:00 [queued]>
[2024-12-17T09:28:19.106+0000] {taskinstance.py:1157} INFO - Dependencies all met for dep_context=requeueable deps ti=<TaskInstance: sick_leave_etl_dag.load_data manual__2024-12-17T09:28:14.856420+00:00 [queued]>
[2024-12-17T09:28:19.107+0000] {taskinstance.py:1359} INFO - Starting attempt 1 of 2
[2024-12-17T09:28:19.119+0000] {taskinstance.py:1380} INFO - Executing <Task(PythonOperator): load_data> on 2024-12-17 09:28:14.856420+00:00
[2024-12-17T09:28:19.123+0000] {standard_task_runner.py:57} INFO - Started process 13266 to run task
[2024-12-17T09:28:19.125+0000] {standard_task_runner.py:84} INFO - Running: ['***', 'tasks', 'run', 'sick_leave_etl_dag', 'load_data', 'manual__2024-12-17T09:28:14.856420+00:00', '--job-id', '145', '--raw', '--subdir', 'DAGS_FOLDER/sick_leave_dag.py', '--cfg-path', '/tmp/tmpk80lkvwn']
[2024-12-17T09:28:19.127+0000] {standard_task_runner.py:85} INFO - Job 145: Subtask load_data
[2024-12-17T09:28:19.142+0000] {logging_mixin.py:151} WARNING - /home/***/.local/lib/python3.8/site-packages/***/settings.py:195 DeprecationWarning: The sql_alchemy_conn option in [core] has been moved to the sql_alchemy_conn option in [database] - the old setting has been used, but please update your config.
[2024-12-17T09:28:19.172+0000] {task_command.py:415} INFO - Running <TaskInstance: sick_leave_etl_dag.load_data manual__2024-12-17T09:28:14.856420+00:00 [running]> on host cfbf61ae1f16
[2024-12-17T09:28:19.249+0000] {taskinstance.py:1660} INFO - Exporting env vars: AIRFLOW_CTX_DAG_OWNER='***' AIRFLOW_CTX_DAG_ID='sick_leave_etl_dag' AIRFLOW_CTX_TASK_ID='load_data' AIRFLOW_CTX_EXECUTION_DATE='2024-12-17T09:28:14.856420+00:00' AIRFLOW_CTX_TRY_NUMBER='1' AIRFLOW_CTX_DAG_RUN_ID='manual__2024-12-17T09:28:14.856420+00:00'
[2024-12-17T09:28:19.263+0000] {base.py:73} INFO - Using connection ID 'admin' for task execution.
[2024-12-17T09:28:19.289+0000] {taskinstance.py:1935} ERROR - Task failed with exception
Traceback (most recent call last):
  File "/home/airflow/.local/lib/python3.8/site-packages/airflow/operators/python.py", line 192, in execute
    return_value = self.execute_callable()
  File "/home/airflow/.local/lib/python3.8/site-packages/airflow/operators/python.py", line 209, in execute_callable
    return self.python_callable(*self.op_args, **self.op_kwargs)
  File "/opt/airflow/dags/sick_leave_dag.py", line 62, in load_data_to_db
    Base.metadata.create_all(engine)
  File "/home/airflow/.local/lib/python3.8/site-packages/sqlalchemy/sql/schema.py", line 4930, in create_all
    bind._run_ddl_visitor(
  File "/home/airflow/.local/lib/python3.8/site-packages/sqlalchemy/engine/base.py", line 3238, in _run_ddl_visitor
    conn._run_ddl_visitor(visitorcallable, element, **kwargs)
  File "/home/airflow/.local/lib/python3.8/site-packages/sqlalchemy/engine/base.py", line 2221, in _run_ddl_visitor
    visitorcallable(self.dialect, self, **kwargs).traverse_single(element)
  File "/home/airflow/.local/lib/python3.8/site-packages/sqlalchemy/sql/visitors.py", line 524, in traverse_single
    return meth(obj, **kw)
  File "/home/airflow/.local/lib/python3.8/site-packages/sqlalchemy/sql/ddl.py", line 831, in visit_metadata
    collection = sort_tables_and_constraints(
  File "/home/airflow/.local/lib/python3.8/site-packages/sqlalchemy/sql/ddl.py", line 1295, in sort_tables_and_constraints
    dependent_on = fkc.referred_table
  File "/home/airflow/.local/lib/python3.8/site-packages/sqlalchemy/sql/schema.py", line 3846, in referred_table
    return self.elements[0].column.table
  File "/home/airflow/.local/lib/python3.8/site-packages/sqlalchemy/util/langhelpers.py", line 1113, in __get__
    obj.__dict__[self.__name__] = result = self.fget(obj)
  File "/home/airflow/.local/lib/python3.8/site-packages/sqlalchemy/sql/schema.py", line 2532, in column
    return self._resolve_column()
  File "/home/airflow/.local/lib/python3.8/site-packages/sqlalchemy/sql/schema.py", line 2543, in _resolve_column
    raise exc.NoReferencedTableError(
sqlalchemy.exc.NoReferencedTableError: Foreign key associated with column 'sick_leave.tab_id' could not find table 'tab_id' with which to generate a foreign key to target column 'None'
[2024-12-17T09:28:19.304+0000] {taskinstance.py:1398} INFO - Marking task as UP_FOR_RETRY. dag_id=sick_leave_etl_dag, task_id=load_data, execution_date=20241217T092814, start_date=20241217T092819, end_date=20241217T092819
[2024-12-17T09:28:19.315+0000] {standard_task_runner.py:104} ERROR - Failed to execute job 145 for task load_data (Foreign key associated with column 'sick_leave.tab_id' could not find table 'tab_id' with which to generate a foreign key to target column 'None'; 13266)
[2024-12-17T09:28:19.337+0000] {local_task_job_runner.py:228} INFO - Task exited with return code 1
[2024-12-17T09:28:19.352+0000] {taskinstance.py:2776} INFO - 0 downstream tasks scheduled from follow-on schedule check
