[2024-12-16T20:59:14.547+0000] {taskinstance.py:1157} INFO - Dependencies all met for dep_context=non-requeueable deps ti=<TaskInstance: full_name_dag.load_data manual__2024-12-16T20:59:11.190201+00:00 [queued]>
[2024-12-16T20:59:14.632+0000] {taskinstance.py:1157} INFO - Dependencies all met for dep_context=requeueable deps ti=<TaskInstance: full_name_dag.load_data manual__2024-12-16T20:59:11.190201+00:00 [queued]>
[2024-12-16T20:59:14.633+0000] {taskinstance.py:1359} INFO - Starting attempt 1 of 2
[2024-12-16T20:59:14.644+0000] {taskinstance.py:1380} INFO - Executing <Task(PythonOperator): load_data> on 2024-12-16 20:59:11.190201+00:00
[2024-12-16T20:59:14.648+0000] {standard_task_runner.py:57} INFO - Started process 8853 to run task
[2024-12-16T20:59:14.650+0000] {standard_task_runner.py:84} INFO - Running: ['***', 'tasks', 'run', 'full_name_dag', 'load_data', 'manual__2024-12-16T20:59:11.190201+00:00', '--job-id', '89', '--raw', '--subdir', 'DAGS_FOLDER/full_name_dag.py', '--cfg-path', '/tmp/tmpc1vvidla']
[2024-12-16T20:59:14.652+0000] {standard_task_runner.py:85} INFO - Job 89: Subtask load_data
[2024-12-16T20:59:14.667+0000] {logging_mixin.py:151} WARNING - /home/***/.local/lib/python3.8/site-packages/***/settings.py:195 DeprecationWarning: The sql_alchemy_conn option in [core] has been moved to the sql_alchemy_conn option in [database] - the old setting has been used, but please update your config.
[2024-12-16T20:59:14.699+0000] {task_command.py:415} INFO - Running <TaskInstance: full_name_dag.load_data manual__2024-12-16T20:59:11.190201+00:00 [running]> on host cfbf61ae1f16
[2024-12-16T20:59:14.768+0000] {taskinstance.py:1660} INFO - Exporting env vars: AIRFLOW_CTX_DAG_OWNER='***' AIRFLOW_CTX_DAG_ID='full_name_dag' AIRFLOW_CTX_TASK_ID='load_data' AIRFLOW_CTX_EXECUTION_DATE='2024-12-16T20:59:11.190201+00:00' AIRFLOW_CTX_TRY_NUMBER='1' AIRFLOW_CTX_DAG_RUN_ID='manual__2024-12-16T20:59:11.190201+00:00'
[2024-12-16T20:59:14.799+0000] {base.py:73} INFO - Using connection ID 'admin' for task execution.
[2024-12-16T20:59:14.822+0000] {taskinstance.py:1935} ERROR - Task failed with exception
Traceback (most recent call last):
  File "/home/airflow/.local/lib/python3.8/site-packages/pandas/core/indexes/base.py", line 3653, in get_loc
    return self._engine.get_loc(casted_key)
  File "pandas/_libs/index.pyx", line 147, in pandas._libs.index.IndexEngine.get_loc
  File "pandas/_libs/index.pyx", line 176, in pandas._libs.index.IndexEngine.get_loc
  File "pandas/_libs/hashtable_class_helper.pxi", line 7080, in pandas._libs.hashtable.PyObjectHashTable.get_item
  File "pandas/_libs/hashtable_class_helper.pxi", line 7088, in pandas._libs.hashtable.PyObjectHashTable.get_item
KeyError: 'tab_id'

The above exception was the direct cause of the following exception:

Traceback (most recent call last):
  File "/home/airflow/.local/lib/python3.8/site-packages/airflow/operators/python.py", line 192, in execute
    return_value = self.execute_callable()
  File "/home/airflow/.local/lib/python3.8/site-packages/airflow/operators/python.py", line 209, in execute_callable
    return self.python_callable(*self.op_args, **self.op_kwargs)
  File "/opt/airflow/dags/full_name_dag.py", line 54, in load_data_to_db
    record = session.query(Fullname).filter_by(tab_id=row['tab_id']).first()
  File "/home/airflow/.local/lib/python3.8/site-packages/pandas/core/series.py", line 1007, in __getitem__
    return self._get_value(key)
  File "/home/airflow/.local/lib/python3.8/site-packages/pandas/core/series.py", line 1116, in _get_value
    loc = self.index.get_loc(label)
  File "/home/airflow/.local/lib/python3.8/site-packages/pandas/core/indexes/base.py", line 3655, in get_loc
    raise KeyError(key) from err
KeyError: 'tab_id'
[2024-12-16T20:59:14.834+0000] {taskinstance.py:1398} INFO - Marking task as UP_FOR_RETRY. dag_id=full_name_dag, task_id=load_data, execution_date=20241216T205911, start_date=20241216T205914, end_date=20241216T205914
[2024-12-16T20:59:14.843+0000] {standard_task_runner.py:104} ERROR - Failed to execute job 89 for task load_data ('tab_id'; 8853)
[2024-12-16T20:59:14.863+0000] {local_task_job_runner.py:228} INFO - Task exited with return code 1
[2024-12-16T20:59:14.882+0000] {taskinstance.py:2776} INFO - 0 downstream tasks scheduled from follow-on schedule check
