[2024-12-17T16:05:06.810+0000] {taskinstance.py:1157} INFO - Dependencies all met for dep_context=non-requeueable deps ti=<TaskInstance: main_dag.сreate_tables manual__2024-12-17T16:05:05.589632+00:00 [queued]>
[2024-12-17T16:05:06.817+0000] {taskinstance.py:1157} INFO - Dependencies all met for dep_context=requeueable deps ti=<TaskInstance: main_dag.сreate_tables manual__2024-12-17T16:05:05.589632+00:00 [queued]>
[2024-12-17T16:05:06.817+0000] {taskinstance.py:1359} INFO - Starting attempt 1 of 2
[2024-12-17T16:05:06.829+0000] {taskinstance.py:1380} INFO - Executing <Task(PythonOperator): сreate_tables> on 2024-12-17 16:05:05.589632+00:00
[2024-12-17T16:05:06.832+0000] {standard_task_runner.py:57} INFO - Started process 3411 to run task
[2024-12-17T16:05:06.834+0000] {standard_task_runner.py:84} INFO - Running: ['***', 'tasks', 'run', 'main_dag', 'сreate_tables', 'manual__2024-12-17T16:05:05.589632+00:00', '--job-id', '156', '--raw', '--subdir', 'DAGS_FOLDER/main_dag.py', '--cfg-path', '/tmp/tmpa537xpra']
[2024-12-17T16:05:06.836+0000] {standard_task_runner.py:85} INFO - Job 156: Subtask сreate_tables
[2024-12-17T16:05:06.853+0000] {logging_mixin.py:151} WARNING - /home/***/.local/lib/python3.8/site-packages/***/settings.py:195 DeprecationWarning: The sql_alchemy_conn option in [core] has been moved to the sql_alchemy_conn option in [database] - the old setting has been used, but please update your config.
[2024-12-17T16:05:06.885+0000] {task_command.py:415} INFO - Running <TaskInstance: main_dag.сreate_tables manual__2024-12-17T16:05:05.589632+00:00 [running]> on host 00b941a4a1a3
[2024-12-17T16:05:06.963+0000] {taskinstance.py:1660} INFO - Exporting env vars: AIRFLOW_CTX_DAG_OWNER='***' AIRFLOW_CTX_DAG_ID='main_dag' AIRFLOW_CTX_TASK_ID='сreate_tables' AIRFLOW_CTX_EXECUTION_DATE='2024-12-17T16:05:05.589632+00:00' AIRFLOW_CTX_TRY_NUMBER='1' AIRFLOW_CTX_DAG_RUN_ID='manual__2024-12-17T16:05:05.589632+00:00'
[2024-12-17T16:05:06.974+0000] {base.py:73} INFO - Using connection ID 'admin' for task execution.
[2024-12-17T16:05:07.097+0000] {taskinstance.py:1935} ERROR - Task failed with exception
Traceback (most recent call last):
  File "/home/airflow/.local/lib/python3.8/site-packages/sqlalchemy/engine/base.py", line 1910, in _execute_context
    self.dialect.do_execute(
  File "/home/airflow/.local/lib/python3.8/site-packages/sqlalchemy/engine/default.py", line 736, in do_execute
    cursor.execute(statement, parameters)
psycopg2.errors.InvalidForeignKey: there is no unique constraint matching given keys for referenced table "data_users"


The above exception was the direct cause of the following exception:

Traceback (most recent call last):
  File "/home/airflow/.local/lib/python3.8/site-packages/airflow/operators/python.py", line 192, in execute
    return_value = self.execute_callable()
  File "/home/airflow/.local/lib/python3.8/site-packages/airflow/operators/python.py", line 209, in execute_callable
    return self.python_callable(*self.op_args, **self.op_kwargs)
  File "/opt/airflow/dags/main_dag.py", line 119, in get_db_engine
    Base.metadata.create_all(engine)
  File "/home/airflow/.local/lib/python3.8/site-packages/sqlalchemy/sql/schema.py", line 4930, in create_all
    bind._run_ddl_visitor(
  File "/home/airflow/.local/lib/python3.8/site-packages/sqlalchemy/engine/base.py", line 3238, in _run_ddl_visitor
    conn._run_ddl_visitor(visitorcallable, element, **kwargs)
  File "/home/airflow/.local/lib/python3.8/site-packages/sqlalchemy/engine/base.py", line 2221, in _run_ddl_visitor
    visitorcallable(self.dialect, self, **kwargs).traverse_single(element)
  File "/home/airflow/.local/lib/python3.8/site-packages/sqlalchemy/sql/visitors.py", line 524, in traverse_single
    return meth(obj, **kw)
  File "/home/airflow/.local/lib/python3.8/site-packages/sqlalchemy/sql/ddl.py", line 855, in visit_metadata
    self.traverse_single(
  File "/home/airflow/.local/lib/python3.8/site-packages/sqlalchemy/sql/visitors.py", line 524, in traverse_single
    return meth(obj, **kw)
  File "/home/airflow/.local/lib/python3.8/site-packages/sqlalchemy/sql/ddl.py", line 899, in visit_table
    self.connection.execute(
  File "/home/airflow/.local/lib/python3.8/site-packages/sqlalchemy/engine/base.py", line 1385, in execute
    return meth(self, multiparams, params, _EMPTY_EXECUTION_OPTS)
  File "/home/airflow/.local/lib/python3.8/site-packages/sqlalchemy/sql/ddl.py", line 80, in _execute_on_connection
    return connection._execute_ddl(
  File "/home/airflow/.local/lib/python3.8/site-packages/sqlalchemy/engine/base.py", line 1477, in _execute_ddl
    ret = self._execute_context(
  File "/home/airflow/.local/lib/python3.8/site-packages/sqlalchemy/engine/base.py", line 1953, in _execute_context
    self._handle_dbapi_exception(
  File "/home/airflow/.local/lib/python3.8/site-packages/sqlalchemy/engine/base.py", line 2134, in _handle_dbapi_exception
    util.raise_(
  File "/home/airflow/.local/lib/python3.8/site-packages/sqlalchemy/util/compat.py", line 211, in raise_
    raise exception
  File "/home/airflow/.local/lib/python3.8/site-packages/sqlalchemy/engine/base.py", line 1910, in _execute_context
    self.dialect.do_execute(
  File "/home/airflow/.local/lib/python3.8/site-packages/sqlalchemy/engine/default.py", line 736, in do_execute
    cursor.execute(statement, parameters)
sqlalchemy.exc.ProgrammingError: (psycopg2.errors.InvalidForeignKey) there is no unique constraint matching given keys for referenced table "data_users"

[SQL: 
CREATE TABLE monthly_collection (
	num SERIAL NOT NULL, 
	sector INTEGER, 
	tab_id INTEGER, 
	change INTEGER, 
	date DATE, 
	info VARCHAR, 
	PRIMARY KEY (num), 
	FOREIGN KEY(sector) REFERENCES data_users (sector), 
	FOREIGN KEY(tab_id) REFERENCES full_name (tab_id), 
	FOREIGN KEY(change) REFERENCES data_users (change)
)

]
(Background on this error at: https://sqlalche.me/e/14/f405)
[2024-12-17T16:05:07.111+0000] {taskinstance.py:1398} INFO - Marking task as UP_FOR_RETRY. dag_id=main_dag, task_id=сreate_tables, execution_date=20241217T160505, start_date=20241217T160506, end_date=20241217T160507
[2024-12-17T16:05:07.120+0000] {standard_task_runner.py:104} ERROR - Failed to execute job 156 for task сreate_tables ((psycopg2.errors.InvalidForeignKey) there is no unique constraint matching given keys for referenced table "data_users"

[SQL: 
CREATE TABLE monthly_collection (
	num SERIAL NOT NULL, 
	sector INTEGER, 
	tab_id INTEGER, 
	change INTEGER, 
	date DATE, 
	info VARCHAR, 
	PRIMARY KEY (num), 
	FOREIGN KEY(sector) REFERENCES data_users (sector), 
	FOREIGN KEY(tab_id) REFERENCES full_name (tab_id), 
	FOREIGN KEY(change) REFERENCES data_users (change)
)

]
(Background on this error at: https://sqlalche.me/e/14/f405); 3411)
[2024-12-17T16:05:07.127+0000] {local_task_job_runner.py:228} INFO - Task exited with return code 1
[2024-12-17T16:05:07.143+0000] {taskinstance.py:2776} INFO - 0 downstream tasks scheduled from follow-on schedule check
