[2024-12-12T19:56:10.532+0000] {taskinstance.py:1157} INFO - Dependencies all met for dep_context=non-requeueable deps ti=<TaskInstance: test_postgres_connection.test_postgres_connection manual__2024-12-12T19:56:09.584042+00:00 [queued]>
[2024-12-12T19:56:10.539+0000] {taskinstance.py:1157} INFO - Dependencies all met for dep_context=requeueable deps ti=<TaskInstance: test_postgres_connection.test_postgres_connection manual__2024-12-12T19:56:09.584042+00:00 [queued]>
[2024-12-12T19:56:10.539+0000] {taskinstance.py:1359} INFO - Starting attempt 1 of 1
[2024-12-12T19:56:10.552+0000] {taskinstance.py:1380} INFO - Executing <Task(PostgresOperator): test_postgres_connection> on 2024-12-12 19:56:09.584042+00:00
[2024-12-12T19:56:10.556+0000] {standard_task_runner.py:57} INFO - Started process 211 to run task
[2024-12-12T19:56:10.559+0000] {standard_task_runner.py:84} INFO - Running: ['***', 'tasks', 'run', 'test_postgres_connection', 'test_postgres_connection', 'manual__2024-12-12T19:56:09.584042+00:00', '--job-id', '3', '--raw', '--subdir', 'DAGS_FOLDER/my_first_dag.py', '--cfg-path', '/tmp/tmposb0qfox']
[2024-12-12T19:56:10.562+0000] {standard_task_runner.py:85} INFO - Job 3: Subtask test_postgres_connection
[2024-12-12T19:56:10.579+0000] {logging_mixin.py:151} WARNING - /home/***/.local/lib/python3.8/site-packages/***/settings.py:195 DeprecationWarning: The sql_alchemy_conn option in [core] has been moved to the sql_alchemy_conn option in [database] - the old setting has been used, but please update your config.
[2024-12-12T19:56:10.619+0000] {task_command.py:415} INFO - Running <TaskInstance: test_postgres_connection.test_postgres_connection manual__2024-12-12T19:56:09.584042+00:00 [running]> on host af7f9afe6e38
[2024-12-12T19:56:10.707+0000] {taskinstance.py:1660} INFO - Exporting env vars: AIRFLOW_CTX_DAG_OWNER='***' AIRFLOW_CTX_DAG_ID='test_postgres_connection' AIRFLOW_CTX_TASK_ID='test_postgres_connection' AIRFLOW_CTX_EXECUTION_DATE='2024-12-12T19:56:09.584042+00:00' AIRFLOW_CTX_TRY_NUMBER='1' AIRFLOW_CTX_DAG_RUN_ID='manual__2024-12-12T19:56:09.584042+00:00'
[2024-12-12T19:56:10.708+0000] {sql.py:274} INFO - Executing: SELECT 1;
[2024-12-12T19:56:10.718+0000] {base.py:73} INFO - Using connection ID '***' for task execution.
[2024-12-12T19:56:10.729+0000] {base.py:73} INFO - Using connection ID '***' for task execution.
[2024-12-12T19:56:10.736+0000] {taskinstance.py:1935} ERROR - Task failed with exception
Traceback (most recent call last):
  File "/home/airflow/.local/lib/python3.8/site-packages/airflow/providers/common/sql/operators/sql.py", line 280, in execute
    output = hook.run(
  File "/home/airflow/.local/lib/python3.8/site-packages/airflow/providers/common/sql/hooks/sql.py", line 385, in run
    with closing(self.get_conn()) as conn:
  File "/home/airflow/.local/lib/python3.8/site-packages/airflow/providers/postgres/hooks/postgres.py", line 154, in get_conn
    self.conn = psycopg2.connect(**conn_args)
  File "/home/airflow/.local/lib/python3.8/site-packages/psycopg2/__init__.py", line 122, in connect
    conn = _connect(dsn, connection_factory=connection_factory, **kwasync)
psycopg2.OperationalError: connection to server at "postgres" (172.18.0.2), port 5432 failed: FATAL:  password authentication failed for user "***"

[2024-12-12T19:56:10.747+0000] {taskinstance.py:1398} INFO - Marking task as FAILED. dag_id=test_postgres_connection, task_id=test_postgres_connection, execution_date=20241212T195609, start_date=20241212T195610, end_date=20241212T195610
[2024-12-12T19:56:10.756+0000] {standard_task_runner.py:104} ERROR - Failed to execute job 3 for task test_postgres_connection (connection to server at "postgres" (172.18.0.2), port 5432 failed: FATAL:  password authentication failed for user "***"
; 211)
[2024-12-12T19:56:10.771+0000] {local_task_job_runner.py:228} INFO - Task exited with return code 1
[2024-12-12T19:56:10.787+0000] {taskinstance.py:2776} INFO - 0 downstream tasks scheduled from follow-on schedule check
