[2024-12-24T21:11:52.523+0000] {taskinstance.py:1157} INFO - Dependencies all met for dep_context=non-requeueable deps ti=<TaskInstance: education_inventory_medical_object_vocation_dag.load_data_5 manual__2024-12-24T21:06:37.710964+00:00 [queued]>
[2024-12-24T21:11:52.531+0000] {taskinstance.py:1157} INFO - Dependencies all met for dep_context=requeueable deps ti=<TaskInstance: education_inventory_medical_object_vocation_dag.load_data_5 manual__2024-12-24T21:06:37.710964+00:00 [queued]>
[2024-12-24T21:11:52.532+0000] {taskinstance.py:1359} INFO - Starting attempt 1 of 2
[2024-12-24T21:11:52.544+0000] {taskinstance.py:1380} INFO - Executing <Task(PythonOperator): load_data_5> on 2024-12-24 21:06:37.710964+00:00
[2024-12-24T21:11:52.549+0000] {standard_task_runner.py:57} INFO - Started process 3396 to run task
[2024-12-24T21:11:52.552+0000] {standard_task_runner.py:84} INFO - Running: ['***', 'tasks', 'run', 'education_inventory_medical_object_vocation_dag', 'load_data_5', 'manual__2024-12-24T21:06:37.710964+00:00', '--job-id', '244', '--raw', '--subdir', 'DAGS_FOLDER/education_inventory_medical_object_vocation_dag.py', '--cfg-path', '/tmp/tmpok68ngj6']
[2024-12-24T21:11:52.555+0000] {standard_task_runner.py:85} INFO - Job 244: Subtask load_data_5
[2024-12-24T21:11:52.573+0000] {logging_mixin.py:151} WARNING - /home/***/.local/lib/python3.8/site-packages/***/settings.py:195 DeprecationWarning: The sql_alchemy_conn option in [core] has been moved to the sql_alchemy_conn option in [database] - the old setting has been used, but please update your config.
[2024-12-24T21:11:52.610+0000] {task_command.py:415} INFO - Running <TaskInstance: education_inventory_medical_object_vocation_dag.load_data_5 manual__2024-12-24T21:06:37.710964+00:00 [running]> on host f7bedf4d7c26
[2024-12-24T21:11:52.698+0000] {taskinstance.py:1660} INFO - Exporting env vars: AIRFLOW_CTX_DAG_OWNER='***' AIRFLOW_CTX_DAG_ID='education_inventory_medical_object_vocation_dag' AIRFLOW_CTX_TASK_ID='load_data_5' AIRFLOW_CTX_EXECUTION_DATE='2024-12-24T21:06:37.710964+00:00' AIRFLOW_CTX_TRY_NUMBER='1' AIRFLOW_CTX_DAG_RUN_ID='manual__2024-12-24T21:06:37.710964+00:00'
[2024-12-24T21:11:53.044+0000] {base.py:73} INFO - Using connection ID 'admin' for task execution.
[2024-12-24T21:11:54.408+0000] {taskinstance.py:1935} ERROR - Task failed with exception
Traceback (most recent call last):
  File "/home/airflow/.local/lib/python3.8/site-packages/sqlalchemy/engine/base.py", line 1910, in _execute_context
    self.dialect.do_execute(
  File "/home/airflow/.local/lib/python3.8/site-packages/sqlalchemy/engine/default.py", line 736, in do_execute
    cursor.execute(statement, parameters)
psycopg2.errors.UniqueViolation: duplicate key value violates unique constraint "vacation_pkey"
DETAIL:  Key (tab_id)=(100) already exists.


The above exception was the direct cause of the following exception:

Traceback (most recent call last):
  File "/home/airflow/.local/lib/python3.8/site-packages/airflow/operators/python.py", line 192, in execute
    return_value = self.execute_callable()
  File "/home/airflow/.local/lib/python3.8/site-packages/airflow/operators/python.py", line 209, in execute_callable
    return self.python_callable(*self.op_args, **self.op_kwargs)
  File "/opt/airflow/dags/education_inventory_medical_object_vocation_dag.py", line 102, in load_data_to_db_5
    record = session.query(Vacation).filter_by(tab_id=row['tab_id']).first()
  File "/home/airflow/.local/lib/python3.8/site-packages/sqlalchemy/orm/query.py", line 2824, in first
    return self.limit(1)._iter().first()
  File "/home/airflow/.local/lib/python3.8/site-packages/sqlalchemy/orm/query.py", line 2916, in _iter
    result = self.session.execute(
  File "/home/airflow/.local/lib/python3.8/site-packages/sqlalchemy/orm/session.py", line 1665, in execute
    ) = compile_state_cls.orm_pre_session_exec(
  File "/home/airflow/.local/lib/python3.8/site-packages/sqlalchemy/orm/context.py", line 312, in orm_pre_session_exec
    session._autoflush()
  File "/home/airflow/.local/lib/python3.8/site-packages/sqlalchemy/orm/session.py", line 2264, in _autoflush
    util.raise_(e, with_traceback=sys.exc_info()[2])
  File "/home/airflow/.local/lib/python3.8/site-packages/sqlalchemy/util/compat.py", line 211, in raise_
    raise exception
  File "/home/airflow/.local/lib/python3.8/site-packages/sqlalchemy/orm/session.py", line 2253, in _autoflush
    self.flush()
  File "/home/airflow/.local/lib/python3.8/site-packages/sqlalchemy/orm/session.py", line 3449, in flush
    self._flush(objects)
  File "/home/airflow/.local/lib/python3.8/site-packages/sqlalchemy/orm/session.py", line 3589, in _flush
    transaction.rollback(_capture_exception=True)
  File "/home/airflow/.local/lib/python3.8/site-packages/sqlalchemy/util/langhelpers.py", line 70, in __exit__
    compat.raise_(
  File "/home/airflow/.local/lib/python3.8/site-packages/sqlalchemy/util/compat.py", line 211, in raise_
    raise exception
  File "/home/airflow/.local/lib/python3.8/site-packages/sqlalchemy/orm/session.py", line 3549, in _flush
    flush_context.execute()
  File "/home/airflow/.local/lib/python3.8/site-packages/sqlalchemy/orm/unitofwork.py", line 456, in execute
    rec.execute(self)
  File "/home/airflow/.local/lib/python3.8/site-packages/sqlalchemy/orm/unitofwork.py", line 630, in execute
    util.preloaded.orm_persistence.save_obj(
  File "/home/airflow/.local/lib/python3.8/site-packages/sqlalchemy/orm/persistence.py", line 245, in save_obj
    _emit_insert_statements(
  File "/home/airflow/.local/lib/python3.8/site-packages/sqlalchemy/orm/persistence.py", line 1097, in _emit_insert_statements
    c = connection._execute_20(
  File "/home/airflow/.local/lib/python3.8/site-packages/sqlalchemy/engine/base.py", line 1710, in _execute_20
    return meth(self, args_10style, kwargs_10style, execution_options)
  File "/home/airflow/.local/lib/python3.8/site-packages/sqlalchemy/sql/elements.py", line 334, in _execute_on_connection
    return connection._execute_clauseelement(
  File "/home/airflow/.local/lib/python3.8/site-packages/sqlalchemy/engine/base.py", line 1577, in _execute_clauseelement
    ret = self._execute_context(
  File "/home/airflow/.local/lib/python3.8/site-packages/sqlalchemy/engine/base.py", line 1953, in _execute_context
    self._handle_dbapi_exception(
  File "/home/airflow/.local/lib/python3.8/site-packages/sqlalchemy/engine/base.py", line 2134, in _handle_dbapi_exception
    util.raise_(
  File "/home/airflow/.local/lib/python3.8/site-packages/sqlalchemy/util/compat.py", line 211, in raise_
    raise exception
  File "/home/airflow/.local/lib/python3.8/site-packages/sqlalchemy/engine/base.py", line 1910, in _execute_context
    self.dialect.do_execute(
  File "/home/airflow/.local/lib/python3.8/site-packages/sqlalchemy/engine/default.py", line 736, in do_execute
    cursor.execute(statement, parameters)
sqlalchemy.exc.IntegrityError: (raised as a result of Query-invoked autoflush; consider using a session.no_autoflush block if this flush is occurring prematurely)
(psycopg2.errors.UniqueViolation) duplicate key value violates unique constraint "vacation_pkey"
DETAIL:  Key (tab_id)=(100) already exists.

[SQL: INSERT INTO vacation (tab_id, vacation_start_1, vacation_stop_1, vacation_start_2, vacation_stop_2) VALUES (%(tab_id)s, %(vacation_start_1)s, %(vacation_stop_1)s, %(vacation_start_2)s, %(vacation_stop_2)s)]
[parameters: {'tab_id': 100, 'vacation_start_1': datetime.date(2025, 1, 1), 'vacation_stop_1': datetime.date(2025, 1, 1), 'vacation_start_2': datetime.date(2025, 1, 1), 'vacation_stop_2': datetime.date(2025, 1, 1)}]
(Background on this error at: https://sqlalche.me/e/14/gkpj)
[2024-12-24T21:11:54.424+0000] {taskinstance.py:1398} INFO - Marking task as UP_FOR_RETRY. dag_id=education_inventory_medical_object_vocation_dag, task_id=load_data_5, execution_date=20241224T210637, start_date=20241224T211152, end_date=20241224T211154
[2024-12-24T21:11:54.438+0000] {standard_task_runner.py:104} ERROR - Failed to execute job 244 for task load_data_5 ((raised as a result of Query-invoked autoflush; consider using a session.no_autoflush block if this flush is occurring prematurely)
(psycopg2.errors.UniqueViolation) duplicate key value violates unique constraint "vacation_pkey"
DETAIL:  Key (tab_id)=(100) already exists.

[SQL: INSERT INTO vacation (tab_id, vacation_start_1, vacation_stop_1, vacation_start_2, vacation_stop_2) VALUES (%(tab_id)s, %(vacation_start_1)s, %(vacation_stop_1)s, %(vacation_start_2)s, %(vacation_stop_2)s)]
[parameters: {'tab_id': 100, 'vacation_start_1': datetime.date(2025, 1, 1), 'vacation_stop_1': datetime.date(2025, 1, 1), 'vacation_start_2': datetime.date(2025, 1, 1), 'vacation_stop_2': datetime.date(2025, 1, 1)}]
(Background on this error at: https://sqlalche.me/e/14/gkpj); 3396)
[2024-12-24T21:11:54.449+0000] {local_task_job_runner.py:228} INFO - Task exited with return code 1
[2024-12-24T21:11:54.468+0000] {taskinstance.py:2776} INFO - 0 downstream tasks scheduled from follow-on schedule check
