[2024-12-24T21:04:31.933+0000] {taskinstance.py:1157} INFO - Dependencies all met for dep_context=non-requeueable deps ti=<TaskInstance: education_inventory_medical_object_vocation_dag.load_data_4 manual__2024-12-24T21:04:22.389232+00:00 [queued]>
[2024-12-24T21:04:31.941+0000] {taskinstance.py:1157} INFO - Dependencies all met for dep_context=requeueable deps ti=<TaskInstance: education_inventory_medical_object_vocation_dag.load_data_4 manual__2024-12-24T21:04:22.389232+00:00 [queued]>
[2024-12-24T21:04:31.942+0000] {taskinstance.py:1359} INFO - Starting attempt 1 of 2
[2024-12-24T21:04:31.955+0000] {taskinstance.py:1380} INFO - Executing <Task(PythonOperator): load_data_4> on 2024-12-24 21:04:22.389232+00:00
[2024-12-24T21:04:31.959+0000] {standard_task_runner.py:57} INFO - Started process 2837 to run task
[2024-12-24T21:04:31.962+0000] {standard_task_runner.py:84} INFO - Running: ['***', 'tasks', 'run', 'education_inventory_medical_object_vocation_dag', 'load_data_4', 'manual__2024-12-24T21:04:22.389232+00:00', '--job-id', '225', '--raw', '--subdir', 'DAGS_FOLDER/education_inventory_medical_object_vocation_dag.py', '--cfg-path', '/tmp/tmpyq6zv3e4']
[2024-12-24T21:04:31.965+0000] {standard_task_runner.py:85} INFO - Job 225: Subtask load_data_4
[2024-12-24T21:04:31.983+0000] {logging_mixin.py:151} WARNING - /home/***/.local/lib/python3.8/site-packages/***/settings.py:195 DeprecationWarning: The sql_alchemy_conn option in [core] has been moved to the sql_alchemy_conn option in [database] - the old setting has been used, but please update your config.
[2024-12-24T21:04:32.021+0000] {task_command.py:415} INFO - Running <TaskInstance: education_inventory_medical_object_vocation_dag.load_data_4 manual__2024-12-24T21:04:22.389232+00:00 [running]> on host f7bedf4d7c26
[2024-12-24T21:04:32.099+0000] {taskinstance.py:1660} INFO - Exporting env vars: AIRFLOW_CTX_DAG_OWNER='***' AIRFLOW_CTX_DAG_ID='education_inventory_medical_object_vocation_dag' AIRFLOW_CTX_TASK_ID='load_data_4' AIRFLOW_CTX_EXECUTION_DATE='2024-12-24T21:04:22.389232+00:00' AIRFLOW_CTX_TRY_NUMBER='1' AIRFLOW_CTX_DAG_RUN_ID='manual__2024-12-24T21:04:22.389232+00:00'
[2024-12-24T21:04:32.424+0000] {base.py:73} INFO - Using connection ID 'admin' for task execution.
[2024-12-24T21:04:32.434+0000] {taskinstance.py:1935} ERROR - Task failed with exception
Traceback (most recent call last):
  File "/home/airflow/.local/lib/python3.8/site-packages/pandas/core/indexes/base.py", line 3653, in get_loc
    return self._engine.get_loc(casted_key)
  File "pandas/_libs/index.pyx", line 147, in pandas._libs.index.IndexEngine.get_loc
  File "pandas/_libs/index.pyx", line 176, in pandas._libs.index.IndexEngine.get_loc
  File "pandas/_libs/hashtable_class_helper.pxi", line 7080, in pandas._libs.hashtable.PyObjectHashTable.get_item
  File "pandas/_libs/hashtable_class_helper.pxi", line 7088, in pandas._libs.hashtable.PyObjectHashTable.get_item
KeyError: 'object'

The above exception was the direct cause of the following exception:

Traceback (most recent call last):
  File "/home/airflow/.local/lib/python3.8/site-packages/airflow/operators/python.py", line 192, in execute
    return_value = self.execute_callable()
  File "/home/airflow/.local/lib/python3.8/site-packages/airflow/operators/python.py", line 209, in execute_callable
    return self.python_callable(*self.op_args, **self.op_kwargs)
  File "/opt/airflow/dags/education_inventory_medical_object_vocation_dag.py", line 84, in load_data_to_db_4
    record = session.query(Object).filter_by(object=row['object']).first()
  File "/home/airflow/.local/lib/python3.8/site-packages/pandas/core/series.py", line 1007, in __getitem__
    return self._get_value(key)
  File "/home/airflow/.local/lib/python3.8/site-packages/pandas/core/series.py", line 1116, in _get_value
    loc = self.index.get_loc(label)
  File "/home/airflow/.local/lib/python3.8/site-packages/pandas/core/indexes/base.py", line 3655, in get_loc
    raise KeyError(key) from err
KeyError: 'object'
[2024-12-24T21:04:32.454+0000] {taskinstance.py:1398} INFO - Marking task as UP_FOR_RETRY. dag_id=education_inventory_medical_object_vocation_dag, task_id=load_data_4, execution_date=20241224T210422, start_date=20241224T210431, end_date=20241224T210432
[2024-12-24T21:04:32.475+0000] {standard_task_runner.py:104} ERROR - Failed to execute job 225 for task load_data_4 ('object'; 2837)
[2024-12-24T21:04:32.496+0000] {local_task_job_runner.py:228} INFO - Task exited with return code 1
[2024-12-24T21:04:32.531+0000] {taskinstance.py:2776} INFO - 0 downstream tasks scheduled from follow-on schedule check
